<?xml version="1.0"?>
<robot xmlns:xacro="http://www.ros.org/wiki/xacro" name="face">
    <!-- Mesh from https://www.blendswap.com/blends/view/74733-->

    <xacro:macro name="face">
        
    <link name="base_link">
	<inertial>
                <origin xyz="0 0 0" rpy="0 0 0"/>
                <mass value="${joints_mass}" />
                <box_inertia 
				m="${base_mass}" 
				x="${base_short}" 
				y="${base_short}" 
				z="${base_long}"/>
				
            </inertial>
            <collision>
                <origin xyz="0 0 0" rpy="0 0 0"/>
                <geometry>
                    <box size="${base_short} ${base_short} ${base_long}"/>
                </geometry>
            </collision>
            <visual>
                <origin rpy="0.0 0 0" xyz="0 0 0"/>
                <geometry>
                    <box size="${base_short} ${base_short} ${base_long}"/>
                </geometry>
            </visual>
	</link>
    
        <joint name="world_faceankor_joint" type="fixed">
            <parent link="world"/>
            <child link="base_link"/>
            <origin xyz="0.0 0.0 0.0" rpy="0 0 0"/>
        </joint>
        
	<link name="yaw_link">
     	    <inertial>
                <origin xyz="0 0 0" rpy="0 0 0"/>
                <mass value="${joints_mass}" />
                <box_inertia 
				m="${joints_mass}" 
				x="${joints_short}" 
				y="${joints_short}" 
				z="${joints_long}"/>
				
            </inertial>
            <collision>
                <origin xyz="0 0 0" rpy="0 0 0"/>
                <geometry>
                    <box size="${joints_short} ${joints_short} ${joints_long}"/>
                </geometry>
            </collision>
            <visual>
                <origin rpy="0.0 0 0" xyz="0 0 0"/>
                <geometry>
                    <box size="${joints_short} ${joints_short} ${joints_long}"/>
                </geometry>
            </visual>
        </link>
        
        <gazebo reference="yaw_link">
            <kp>100000.0</kp>
            <kd>100000.0</kd>
            <mu1>10.0</mu1>
            <mu2>10.0</mu2>
            <material>Gazebo/Blue</material>
        </gazebo>

        <joint name="yaw_joint" type="continuous">
        	<parent link="base_link"/>
            <child link="yaw_link"/>
            <origin xyz="0.0 0.0 0.0" rpy="0 0 0"/>
            <limit effort="${joint_yaw_max_effort}" velocity="${joint_yaw_max_speed}"/>
            <axis xyz="0 0 1"/>
	    </joint>
	    
    	<transmission name="tran1">
            <type>transmission_interface/SimpleTransmission</type>
            <joint name="yaw_joint">
                <hardwareInterface>EffortJointInterface</hardwareInterface>
            </joint>
            <actuator name="motor1">
                <hardwareInterface>EffortJointInterface</hardwareInterface>
                <mechanicalReduction>1</mechanicalReduction>
            </actuator>
        </transmission>
    
	    
    	<link name="pitch_link">
     	    <inertial>
                <origin xyz="0 0 0" rpy="0 0 0"/>
                <mass value="${joints_mass}" />
                <box_inertia 
				m="${joints_mass}" 
				x="${joints_short}" 
				y="${joints_long}" 
				z="${joints_short}"/>
				
            </inertial>
            <collision>
                <origin xyz="0 0 0" rpy="0 0 0"/>
                <geometry>
                    <box size="${joints_short} ${joints_long} ${joints_short}"/>
                </geometry>
            </collision>
            <visual>
                <origin rpy="0.0 0 0" xyz="0 0 0"/>
                <geometry>
                    <box size="${joints_short} ${joints_long} ${joints_short}"/>
                </geometry>
            </visual>
        </link>
        
        <gazebo reference="pitch_link">
            <kp>100000.0</kp>
            <kd>100000.0</kd>
            <mu1>10.0</mu1>
            <mu2>10.0</mu2>
            <material>Gazebo/Green</material>
        </gazebo>

	<joint name="pitch_joint" type="revolute">
		<parent link="yaw_link"/>
		<child link="pitch_link"/>
		<origin xyz="0.0 0.0 0.0" rpy="0 0 0"/>
		<limit lower="-0.7" upper="0.7" effort="${joint_pitch_effort}" velocity="${joint_pitch_max_speed}"/>
		<axis xyz="0 1 0"/>
	</joint>
	    
	    
    	<transmission name="tran2">
            <type>transmission_interface/SimpleTransmission</type>
            <joint name="pitch_joint">
                <hardwareInterface>EffortJointInterface</hardwareInterface>
            </joint>
            <actuator name="motor2">
                <hardwareInterface>EffortJointInterface</hardwareInterface>
                <mechanicalReduction>1</mechanicalReduction>
            </actuator>
        </transmission>        
	    
    	

	<link name="face_link">
     	    <inertial>
                <origin xyz="0 0 0" rpy="0 0 0"/>
                <mass value="${face_mass}" />
                <box_inertia 
				m="${face_mass}" 
				x="${face_size_x}" 
				y="${face_size_y}" 
				z="${face_size_z}"/>
				
            </inertial>
            <collision>
                <origin xyz="0 0 0" rpy="0 0 0"/>
                <geometry>
                    <mesh filename="package://pan_and_tilt_description/meshes/head.stl" scale="1 1 1"/>
                </geometry>
            </collision>
            <visual>
                <origin rpy="0.0 0 0" xyz="0 0 0"/>
                <geometry>
                    <mesh filename="package://pan_and_tilt_description/meshes/head.stl" scale="1 1 1"/>
                </geometry>
            </visual>
        </link>
        
        <gazebo reference="face_link">
            <kp>100000.0</kp>
            <kd>100000.0</kd>
            <mu1>10.0</mu1>
            <mu2>10.0</mu2>
            <material>Gazebo/Gold</material>
        </gazebo>

	<joint name="face_joint" type="fixed">
		<parent link="pitch_link"/>
		<child link="face_link"/>
		<origin xyz="0.0 0.0 0.0" rpy="0 0 0"/>
	</joint>


    </xacro:macro>
    
</robot>
